Workbook

Sheet MASTER Verification
A1: Project ID | B1: Project Name | C1: Primary Department | D1: Secondary Department | E1: 1st ADR | F1: 2nd ADR | G1: 3rd ADR | H1: 4th ADR | I1: 5th ADR | J1: 6th ADR
A2: SRP8-001 | B2: Doors | C2: Chassis & Bodywork
A3: SRP8-002 | B3: Door Handles | C3: Chassis & Bodywork
A4: SRP8-003 | B4: Windscreen | C4: Chassis & Bodywork | E4: ADR-93 | F4: ADR-08
A5: SRP8-004 | B5: Boot | C5: Chassis & Bodywork | E5: ADR-43
A6: SRP8-005 | B6: Bonnet | C6: Chassis & Bodywork
A7: SRP8-006 | B7: Exterior Design | C7: Chassis & Bodywork
A8: SRP8-007 | B8: Front Wheel Covers
A9: SRP8-008 | B9: Rear Wheel Covers
A10: SRP8-009 | B10: Chassis
A11: SRP8-010 | B11: Ventilation | C11: Chassis & Bodywork | D11: Energy Systems
A12: SRP8-011 | B12: Tailights | C12: Embedded Systems | D12: Chassis & Bodywork
A13: SRP8-012 | B13: Headlights | C13: Embedded Systems | D13: Chassis & Bodywork | E13: ADR-46 | F13: ADR-92 | G13: ADR-76
A14: SRP8-013 | B14: Indicators | C14: Embedded Systems | D14: Chassis & Bodywork | E14: ADR-13
A15: SRP8-014 | B15: Regen Braking | C15: Embedded Systems
A16: SRP8-015 | B16: Cruise Control | C16: Embedded Systems
A17: SRP8-016 | B17: Battery | C17: Energy Systems | D17: Chassis & Bodywork
A18: SRP8-017 | B18: Auxillary Power Distribution | C18: Energy Systems | D18: Energy Systems
A19: SRP8-018 | B19: Energy Control | C19: Energy Systems
A20: SRP8-019 | B20: MPPTs | C20: Energy Systems
A21: SRP8-020 | B21: Solar Array | C21: Energy Systems | D21: Chassis & Bodywork
A22: SRP8-021 | B22: Charging | C22: Energy Systems | D22: Chassis & Bodywork
A23: SRP8-022 | B23: Steering Wheel | C23: Interior | D23: Embedded Systems | E23: ADR-42 | F23: ADR-10 | G23: ADR-93
A24: SRP8-023 | B24: Interior Lights | C24: Interior | D24: Embedded Systems
A25: SRP8-024 | B25: Rear Vision System | C25: Interior | D25: Chassis & Bodywork
A26: SRP8-025 | B26: Side Vision System | C26: Interior | D26: Chassis & Bodywork
A27: SRP8-026 | B27: Pedals | C27: Interior
A28: SRP8-027 | B28: Ceiling | C28: Interior | D28: Chassis & Bodywork
A29: SRP8-028 | B29: Central Display | C29: Interior | D29: Chassis & Bodywork
A30: SRP8-029 | B30: Driver Display | C30: Interior | D30: Embedded Systems
A31: SRP8-030 | B31: Heads-Up Display
A32: SRP8-031 | B32: 0
A33: SRP8-032 | B33: Front Seats | C33: Interior
A34: SRP8-033 | B34: Rear Seatbelts
A35: SRP8-034 | B35: Front Seatbelts | C35: Interior | E35: ADR-69 | F35: ADR-42
A36: SRP8-035 | B36: Rear Seat Mount
A37: SRP8-036 | B37: Front Seat Mount | C37: Interior
A38: SRP8-037 | B38: Dashboard | C38: Interior
A39: SRP8-038 | B39: Motors | C39: Powertrain | D39: Chassis & Bodywork
A40: SRP8-039 | B40: Powertrain Electronics | C40: Powertrain | D40: Energy Systems
...

Sheet MASTER V&V
A1: Project ID | B1: Project Name | C1: Primary Department | D1: Secondary Department | E1: 1st ADR | F1: 2nd ADR | G1: 3rd ADR | H1: 4th ADR | I1: 5th ADR | J1: 6th ADR
A2: SRP8-001 | B2: Doors | C2: Chassis & Bodywork | E2: =IFERROR( INDEX('Project Assignment Check'!$G$1:$ZX$1, MATCH( LARGE( INDEX('ADR Tracking'!$G:$ZX, MATCH($A2, 'ADR Tracking'!$A:$A, 0), ), COLUMN()-4 ), INDEX('ADR Tracking'!$G:$ZX, MATCH($A2, 'ADR Tracking'!$A:$A, 0), ), 0 ) ), "" ) -> ADR-02 | F2: =IFERROR( INDEX('Project Assignment Check'!$G$1:$ZX$1, MATCH( LARGE( INDEX('ADR Tracking'!$G:$ZX, MATCH($A2, 'ADR Tracking'!$A:$A, 0), ), COLUMN()-4 ), INDEX('ADR Tracking'!$G:$ZX, MATCH($A2, 'ADR Tracking'!$A:$A, 0), ), 0 ) ), "" ) -> ADR-29 | G2: =IFERROR( INDEX('Project Assignment Check'!$G$1:$ZX$1, MATCH( LARGE( INDEX('ADR Tracking'!$G:$ZX, MATCH($A2, 'ADR Tracking'!$A:$A, 0), ), COLUMN()-4 ), INDEX('ADR Tracking'!$G:$ZX, MATCH($A2, 'ADR Tracking'!$A:$A, 0), ), 0 ) ), "" ) -> ADR-93 | H2: =IFERROR( INDEX('Project Assignment Check'!$G$1:$ZX$1, MATCH( LARGE( INDEX('ADR Tracking'!$G:$ZX, MATCH($A2, 'ADR Tracking'!$A:$A, 0), ), COLUMN()-4 ), INDEX('ADR Tracking'!$G:$ZX, MATCH($A2, 'ADR Tracking'!$A:$A, 0), ), 0 ) ), "" ) -> ADR-92 | I2: =IFERROR( INDEX('Project Assignment Check'!$G$1:$ZX$1, MATCH( LARGE( INDEX('ADR Tracking'!$G:$ZX, MATCH($A2, 'ADR Tracking'!$A:$A, 0), ), COLUMN()-4 ), INDEX('ADR Tracking'!$G:$ZX, MATCH($A2, 'ADR Tracking'!$A:$A, 0), ), 0 ) ), "" ) | J2: =IFERROR( INDEX('Project Assignment Check'!$G$1:$ZX$1, MATCH( LARGE( INDEX('ADR Tracking'!$G:$ZX, MATCH($A2, 'ADR Tracking'!$A:$A, 0), ), COLUMN()-4 ), INDEX('ADR Tracking'!$G:$ZX, MATCH($A2, 'ADR Tracking'!$A:$A, 0), ), 0 ) ), "" )
A3: SRP8-002 | B3: Door Handles | C3: Chassis & Bodywork | E3: =IFERROR( INDEX('Project Assignment Check'!$G$1:$ZX$1, MATCH( LARGE( INDEX('ADR Tracking'!$G:$ZX, MATCH($A3, 'ADR Tracking'!$A:$A, 0), ), COLUMN()-4 ), INDEX('ADR Tracking'!$G:$ZX, MATCH($A3, 'ADR Tracking'!$A:$A, 0), ), 0 ) ), "" ) -> ADR-92 | F3: =IFERROR( INDEX('Project Assignment Check'!$G$1:$ZX$1, MATCH( LARGE( INDEX('ADR Tracking'!$G:$ZX, MATCH($A3, 'ADR Tracking'!$A:$A, 0), ), COLUMN()-4 ), INDEX('ADR Tracking'!$G:$ZX, MATCH($A3, 'ADR Tracking'!$A:$A, 0), ), 0 ) ), "" ) | G3: =IFERROR( INDEX('Project Assignment Check'!$G$1:$ZX$1, MATCH( LARGE( INDEX('ADR Tracking'!$G:$ZX, MATCH($A3, 'ADR Tracking'!$A:$A, 0), ), COLUMN()-4 ), INDEX('ADR Tracking'!$G:$ZX, MATCH($A3, 'ADR Tracking'!$A:$A, 0), ), 0 ) ), "" ) | H3: =IFERROR( INDEX('Project Assignment Check'!$G$1:$ZX$1, MATCH( LARGE( INDEX('ADR Tracking'!$G:$ZX, MATCH($A3, 'ADR Tracking'!$A:$A, 0), ), COLUMN()-4 ), INDEX('ADR Tracking'!$G:$ZX, MATCH($A3, 'ADR Tracking'!$A:$A, 0), ), 0 ) ), "" ) | I3: =IFERROR( INDEX('Project Assignment Check'!$G$1:$ZX$1, MATCH( LARGE( INDEX('ADR Tracking'!$G:$ZX, MATCH($A3, 'ADR Tracking'!$A:$A, 0), ), COLUMN()-4 ), INDEX('ADR Tracking'!$G:$ZX, MATCH($A3, 'ADR Tracking'!$A:$A, 0), ), 0 ) ), "" ) | J3: =IFERROR( INDEX('Project Assignment Check'!$G$1:$ZX$1, MATCH( LARGE( INDEX('ADR Tracking'!$G:$ZX, MATCH($A3, 'ADR Tracking'!$A:$A, 0), ), COLUMN()-4 ), INDEX('ADR Tracking'!$G:$ZX, MATCH($A3, 'ADR Tracking'!$A:$A, 0), ), 0 ) ), "" )
A4: SRP8-003 | B4: Windscreen | C4: Chassis & Bodywork | E4: =IFERROR( INDEX('Project Assignment Check'!$G$1:$ZX$1, MATCH( LARGE( INDEX('ADR Tracking'!$G:$ZX, MATCH($A4, 'ADR Tracking'!$A:$A, 0), ), COLUMN()-4 ), INDEX('ADR Tracking'!$G:$ZX, MATCH($A4, 'ADR Tracking'!$A:$A, 0), ), 0 ) ), "" ) -> ADR-08 | F4: =IFERROR( INDEX('Project Assignment Check'!$G$1:$ZX$1, MATCH( LARGE( INDEX('ADR Tracking'!$G:$ZX, MATCH($A4, 'ADR Tracking'!$A:$A, 0), ), COLUMN()-4 ), INDEX('ADR Tracking'!$G:$ZX, MATCH($A4, 'ADR Tracking'!$A:$A, 0), ), 0 ) ), "" ) -> ADR-93 | G4: =IFERROR( INDEX('Project Assignment Check'!$G$1:$ZX$1, MATCH( LARGE( INDEX('ADR Tracking'!$G:$ZX, MATCH($A4, 'ADR Tracking'!$A:$A, 0), ), COLUMN()-4 ), INDEX('ADR Tracking'!$G:$ZX, MATCH($A4, 'ADR Tracking'!$A:$A, 0), ), 0 ) ), "" ) -> ADR-92 | H4: =IFERROR( INDEX('Project Assignment Check'!$G$1:$ZX$1, MATCH( LARGE( INDEX('ADR Tracking'!$G:$ZX, MATCH($A4, 'ADR Tracking'!$A:$A, 0), ), COLUMN()-4 ), INDEX('ADR Tracking'!$G:$ZX, MATCH($A4, 'ADR Tracking'!$A:$A, 0), ), 0 ) ), "" ) | I4: =IFERROR( INDEX('Project Assignment Check'!$G$1:$ZX$1, MATCH( LARGE( INDEX('ADR Tracking'!$G:$ZX, MATCH($A4, 'ADR Tracking'!$A:$A, 0), ), COLUMN()-4 ), INDEX('ADR Tracking'!$G:$ZX, MATCH($A4, 'ADR Tracking'!$A:$A, 0), ), 0 ) ), "" ) | J4: =IFERROR( INDEX('Project Assignment Check'!$G$1:$ZX$1, MATCH( LARGE( INDEX('ADR Tracking'!$G:$ZX, MATCH($A4, 'ADR Tracking'!$A:$A, 0), ), COLUMN()-4 ), INDEX('ADR Tracking'!$G:$ZX, MATCH($A4, 'ADR Tracking'!$A:$A, 0), ), 0 ) ), "" )
A5: SRP8-004 | B5: Boot | C5: Chassis & Bodywork | E5: =IFERROR( INDEX('Project Assignment Check'!$G$1:$ZX$1, MATCH( LARGE( INDEX('ADR Tracking'!$G:$ZX, MATCH($A5, 'ADR Tracking'!$A:$A, 0), ), COLUMN()-4 ), INDEX('ADR Tracking'!$G:$ZX, MATCH($A5, 'ADR Tracking'!$A:$A, 0), ), 0 ) ), "" ) -> ADR-92 | F5: =IFERROR( INDEX('Project Assignment Check'!$G$1:$ZX$1, MATCH( LARGE( INDEX('ADR Tracking'!$G:$ZX, MATCH($A5, 'ADR Tracking'!$A:$A, 0), ), COLUMN()-4 ), INDEX('ADR Tracking'!$G:$ZX, MATCH($A5, 'ADR Tracking'!$A:$A, 0), ), 0 ) ), "" ) -> ADR-43 | G5: =IFERROR( INDEX('Project Assignment Check'!$G$1:$ZX$1, MATCH( LARGE( INDEX('ADR Tracking'!$G:$ZX, MATCH($A5, 'ADR Tracking'!$A:$A, 0), ), COLUMN()-4 ), INDEX('ADR Tracking'!$G:$ZX, MATCH($A5, 'ADR Tracking'!$A:$A, 0), ), 0 ) ), "" ) | H5: =IFERROR( INDEX('Project Assignment Check'!$G$1:$ZX$1, MATCH( LARGE( INDEX('ADR Tracking'!$G:$ZX, MATCH($A5, 'ADR Tracking'!$A:$A, 0), ), COLUMN()-4 ), INDEX('ADR Tracking'!$G:$ZX, MATCH($A5, 'ADR Tracking'!$A:$A, 0), ), 0 ) ), "" ) | I5: =IFERROR( INDEX('Project Assignment Check'!$G$1:$ZX$1, MATCH( LARGE( INDEX('ADR Tracking'!$G:$ZX, MATCH($A5, 'ADR Tracking'!$A:$A, 0), ), COLUMN()-4 ), INDEX('ADR Tracking'!$G:$ZX, MATCH($A5, 'ADR Tracking'!$A:$A, 0), ), 0 ) ), "" ) | J5: =IFERROR( INDEX('Project Assignment Check'!$G$1:$ZX$1, MATCH( LARGE( INDEX('ADR Tracking'!$G:$ZX, MATCH($A5, 'ADR Tracking'!$A:$A, 0), ), COLUMN()-4 ), INDEX('ADR Tracking'!$G:$ZX, MATCH($A5, 'ADR Tracking'!$A:$A, 0), ), 0 ) ), "" )
A6: SRP8-005 | B6: Bonnet | C6: Chassis & Bodywork | E6: =IFERROR( INDEX('Project Assignment Check'!$G$1:$ZX$1, MATCH( LARGE( INDEX('ADR Tracking'!$G:$ZX, MATCH($A6, 'ADR Tracking'!$A:$A, 0), ), COLUMN()-4 ), INDEX('ADR Tracking'!$G:$ZX, MATCH($A6, 'ADR Tracking'!$A:$A, 0), ), 0 ) ), "" ) -> ADR-42 | F6: =IFERROR( INDEX('Project Assignment Check'!$G$1:$ZX$1, MATCH( LARGE( INDEX('ADR Tracking'!$G:$ZX, MATCH($A6, 'ADR Tracking'!$A:$A, 0), ), COLUMN()-4 ), INDEX('ADR Tracking'!$G:$ZX, MATCH($A6, 'ADR Tracking'!$A:$A, 0), ), 0 ) ), "" ) -> ADR-92 | G6: =IFERROR( INDEX('Project Assignment Check'!$G$1:$ZX$1, MATCH( LARGE( INDEX('ADR Tracking'!$G:$ZX, MATCH($A6, 'ADR Tracking'!$A:$A, 0), ), COLUMN()-4 ), INDEX('ADR Tracking'!$G:$ZX, MATCH($A6, 'ADR Tracking'!$A:$A, 0), ), 0 ) ), "" ) | H6: =IFERROR( INDEX('Project Assignment Check'!$G$1:$ZX$1, MATCH( LARGE( INDEX('ADR Tracking'!$G:$ZX, MATCH($A6, 'ADR Tracking'!$A:$A, 0), ), COLUMN()-4 ), INDEX('ADR Tracking'!$G:$ZX, MATCH($A6, 'ADR Tracking'!$A:$A, 0), ), 0 ) ), "" ) | I6: =IFERROR( INDEX('Project Assignment Check'!$G$1:$ZX$1, MATCH( LARGE( INDEX('ADR Tracking'!$G:$ZX, MATCH($A6, 'ADR Tracking'!$A:$A, 0), ), COLUMN()-4 ), INDEX('ADR Tracking'!$G:$ZX, MATCH($A6, 'ADR Tracking'!$A:$A, 0), ), 0 ) ), "" ) | J6: =IFERROR( INDEX('Project Assignment Check'!$G$1:$ZX$1, MATCH( LARGE( INDEX('ADR Tracking'!$G:$ZX, MATCH($A6, 'ADR Tracking'!$A:$A, 0), ), COLUMN()-4 ), INDEX('ADR Tracking'!$G:$ZX, MATCH($A6, 'ADR Tracking'!$A:$A, 0), ), 0 ) ), "" )
A7: SRP8-010 | B7: Ventilation | C7: Chassis & Bodywork | D7: Energy Systems | E7: =IFERROR( INDEX('Project Assignment Check'!$G$1:$ZX$1, MATCH( LARGE( INDEX('ADR Tracking'!$G:$ZX, MATCH($A7, 'ADR Tracking'!$A:$A, 0), ), COLUMN()-4 ), INDEX('ADR Tracking'!$G:$ZX, MATCH($A7, 'ADR Tracking'!$A:$A, 0), ), 0 ) ), "" ) | F7: =IFERROR( INDEX('Project Assignment Check'!$G$1:$ZX$1, MATCH( LARGE( INDEX('ADR Tracking'!$G:$ZX, MATCH($A7, 'ADR Tracking'!$A:$A, 0), ), COLUMN()-4 ), INDEX('ADR Tracking'!$G:$ZX, MATCH($A7, 'ADR Tracking'!$A:$A, 0), ), 0 ) ), "" ) | G7: =IFERROR( INDEX('Project Assignment Check'!$G$1:$ZX$1, MATCH( LARGE( INDEX('ADR Tracking'!$G:$ZX, MATCH($A7, 'ADR Tracking'!$A:$A, 0), ), COLUMN()-4 ), INDEX('ADR Tracking'!$G:$ZX, MATCH($A7, 'ADR Tracking'!$A:$A, 0), ), 0 ) ), "" ) | H7: =IFERROR( INDEX('Project Assignment Check'!$G$1:$ZX$1, MATCH( LARGE( INDEX('ADR Tracking'!$G:$ZX, MATCH($A7, 'ADR Tracking'!$A:$A, 0), ), COLUMN()-4 ), INDEX('ADR Tracking'!$G:$ZX, MATCH($A7, 'ADR Tracking'!$A:$A, 0), ), 0 ) ), "" ) | I7: =IFERROR( INDEX('Project Assignment Check'!$G$1:$ZX$1, MATCH( LARGE( INDEX('ADR Tracking'!$G:$ZX, MATCH($A7, 'ADR Tracking'!$A:$A, 0), ), COLUMN()-4 ), INDEX('ADR Tracking'!$G:$ZX, MATCH($A7, 'ADR Tracking'!$A:$A, 0), ), 0 ) ), "" ) | J7: =IFERROR( INDEX('Project Assignment Check'!$G$1:$ZX$1, MATCH( LARGE( INDEX('ADR Tracking'!$G:$ZX, MATCH($A7, 'ADR Tracking'!$A:$A, 0), ), COLUMN()-4 ), INDEX('ADR Tracking'!$G:$ZX, MATCH($A7, 'ADR Tracking'!$A:$A, 0), ), 0 ) ), "" )
A8: SRP8-011 | B8: Tailights | C8: Embedded Systems | D8: Chassis & Bodywork | E8: =IFERROR( INDEX('Project Assignment Check'!$G$1:$ZX$1, MATCH( LARGE( INDEX('ADR Tracking'!$G:$ZX, MATCH($A8, 'ADR Tracking'!$A:$A, 0), ), COLUMN()-4 ), INDEX('ADR Tracking'!$G:$ZX, MATCH($A8, 'ADR Tracking'!$A:$A, 0), ), 0 ) ), "" ) -> ADR-13 | F8: =IFERROR( INDEX('Project Assignment Check'!$G$1:$ZX$1, MATCH( LARGE( INDEX('ADR Tracking'!$G:$ZX, MATCH($A8, 'ADR Tracking'!$A:$A, 0), ), COLUMN()-4 ), INDEX('ADR Tracking'!$G:$ZX, MATCH($A8, 'ADR Tracking'!$A:$A, 0), ), 0 ) ), "" ) -> ADR-01 | G8: =IFERROR( INDEX('Project Assignment Check'!$G$1:$ZX$1, MATCH( LARGE( INDEX('ADR Tracking'!$G:$ZX, MATCH($A8, 'ADR Tracking'!$A:$A, 0), ), COLUMN()-4 ), INDEX('ADR Tracking'!$G:$ZX, MATCH($A8, 'ADR Tracking'!$A:$A, 0), ), 0 ) ), "" ) -> ADR-49 | H8: =IFERROR( INDEX('Project Assignment Check'!$G$1:$ZX$1, MATCH( LARGE( INDEX('ADR Tracking'!$G:$ZX, MATCH($A8, 'ADR Tracking'!$A:$A, 0), ), COLUMN()-4 ), INDEX('ADR Tracking'!$G:$ZX, MATCH($A8, 'ADR Tracking'!$A:$A, 0), ), 0 ) ), "" ) -> ADR-48 | I8: =IFERROR( INDEX('Project Assignment Check'!$G$1:$ZX$1, MATCH( LARGE( INDEX('ADR Tracking'!$G:$ZX, MATCH($A8, 'ADR Tracking'!$A:$A, 0), ), COLUMN()-4 ), INDEX('ADR Tracking'!$G:$ZX, MATCH($A8, 'ADR Tracking'!$A:$A, 0), ), 0 ) ), "" ) | J8: =IFERROR( INDEX('Project Assignment Check'!$G$1:$ZX$1, MATCH( LARGE( INDEX('ADR Tracking'!$G:$ZX, MATCH($A8, 'ADR Tracking'!$A:$A, 0), ), COLUMN()-4 ), INDEX('ADR Tracking'!$G:$ZX, MATCH($A8, 'ADR Tracking'!$A:$A, 0), ), 0 ) ), "" )
A9: SRP8-012 | B9: Headlights | C9: Embedded Systems | D9: Chassis & Bodywork | E9: =IFERROR( INDEX('Project Assignment Check'!$G$1:$ZX$1, MATCH( LARGE( INDEX('ADR Tracking'!$G:$ZX, MATCH($A9, 'ADR Tracking'!$A:$A, 0), ), COLUMN()-4 ), INDEX('ADR Tracking'!$G:$ZX, MATCH($A9, 'ADR Tracking'!$A:$A, 0), ), 0 ) ), "" ) -> ADR-13 | F9: =IFERROR( INDEX('Project Assignment Check'!$G$1:$ZX$1, MATCH( LARGE( INDEX('ADR Tracking'!$G:$ZX, MATCH($A9, 'ADR Tracking'!$A:$A, 0), ), COLUMN()-4 ), INDEX('ADR Tracking'!$G:$ZX, MATCH($A9, 'ADR Tracking'!$A:$A, 0), ), 0 ) ), "" ) -> ADR-76 | G9: =IFERROR( INDEX('Project Assignment Check'!$G$1:$ZX$1, MATCH( LARGE( INDEX('ADR Tracking'!$G:$ZX, MATCH($A9, 'ADR Tracking'!$A:$A, 0), ), COLUMN()-4 ), INDEX('ADR Tracking'!$G:$ZX, MATCH($A9, 'ADR Tracking'!$A:$A, 0), ), 0 ) ), "" ) -> ADR-46 | H9: =IFERROR( INDEX('Project Assignment Check'!$G$1:$ZX$1, MATCH( LARGE( INDEX('ADR Tracking'!$G:$ZX, MATCH($A9, 'ADR Tracking'!$A:$A, 0), ), COLUMN()-4 ), INDEX('ADR Tracking'!$G:$ZX, MATCH($A9, 'ADR Tracking'!$A:$A, 0), ), 0 ) ), "" ) -> ADR-92 | I9: =IFERROR( INDEX('Project Assignment Check'!$G$1:$ZX$1, MATCH( LARGE( INDEX('ADR Tracking'!$G:$ZX, MATCH($A9, 'ADR Tracking'!$A:$A, 0), ), COLUMN()-4 ), INDEX('ADR Tracking'!$G:$ZX, MATCH($A9, 'ADR Tracking'!$A:$A, 0), ), 0 ) ), "" ) -> ADR-06 | J9: =IFERROR( INDEX('Project Assignment Check'!$G$1:$ZX$1, MATCH( LARGE( INDEX('ADR Tracking'!$G:$ZX, MATCH($A9, 'ADR Tracking'!$A:$A, 0), ), COLUMN()-4 ), INDEX('ADR Tracking'!$G:$ZX, MATCH($A9, 'ADR Tracking'!$A:$A, 0), ), 0 ) ), "" )
A10: SRP8-013 | B10: Indicators | C10: Embedded Systems | D10: Chassis & Bodywork | E10: =IFERROR( INDEX('Project Assignment Check'!$G$1:$ZX$1, MATCH( LARGE( INDEX('ADR Tracking'!$G:$ZX, MATCH($A10, 'ADR Tracking'!$A:$A, 0), ), COLUMN()-4 ), INDEX('ADR Tracking'!$G:$ZX, MATCH($A10, 'ADR Tracking'!$A:$A, 0), ), 0 ) ), "" ) -> ADR-13 | F10: =IFERROR( INDEX('Project Assignment Check'!$G$1:$ZX$1, MATCH( LARGE( INDEX('ADR Tracking'!$G:$ZX, MATCH($A10, 'ADR Tracking'!$A:$A, 0), ), COLUMN()-4 ), INDEX('ADR Tracking'!$G:$ZX, MATCH($A10, 'ADR Tracking'!$A:$A, 0), ), 0 ) ), "" ) -> ADR-06 | G10: =IFERROR( INDEX('Project Assignment Check'!$G$1:$ZX$1, MATCH( LARGE( INDEX('ADR Tracking'!$G:$ZX, MATCH($A10, 'ADR Tracking'!$A:$A, 0), ), COLUMN()-4 ), INDEX('ADR Tracking'!$G:$ZX, MATCH($A10, 'ADR Tracking'!$A:$A, 0), ), 0 ) ), "" ) | H10: =IFERROR( INDEX('Project Assignment Check'!$G$1:$ZX$1, MATCH( LARGE( INDEX('ADR Tracking'!$G:$ZX, MATCH($A10, 'ADR Tracking'!$A:$A, 0), ), COLUMN()-4 ), INDEX('ADR Tracking'!$G:$ZX, MATCH($A10, 'ADR Tracking'!$A:$A, 0), ), 0 ) ), "" ) | I10: =IFERROR( INDEX('Project Assignment Check'!$G$1:$ZX$1, MATCH( LARGE( INDEX('ADR Tracking'!$G:$ZX, MATCH($A10, 'ADR Tracking'!$A:$A, 0), ), COLUMN()-4 ), INDEX('ADR Tracking'!$G:$ZX, MATCH($A10, 'ADR Tracking'!$A:$A, 0), ), 0 ) ), "" ) | J10: =IFERROR( INDEX('Project Assignment Check'!$G$1:$ZX$1, MATCH( LARGE( INDEX('ADR Tracking'!$G:$ZX, MATCH($A10, 'ADR Tracking'!$A:$A, 0), ), COLUMN()-4 ), INDEX('ADR Tracking'!$G:$ZX, MATCH($A10, 'ADR Tracking'!$A:$A, 0), ), 0 ) ), "" )
A11: SRP8-014 | B11: Regen Braking | C11: Embedded Systems | E11: =IFERROR( INDEX('Project Assignment Check'!$G$1:$ZX$1, MATCH( LARGE( INDEX('ADR Tracking'!$G:$ZX, MATCH($A11, 'ADR Tracking'!$A:$A, 0), ), COLUMN()-4 ), INDEX('ADR Tracking'!$G:$ZX, MATCH($A11, 'ADR Tracking'!$A:$A, 0), ), 0 ) ), "" ) -> ADR-31 | F11: =IFERROR( INDEX('Project Assignment Check'!$G$1:$ZX$1, MATCH( LARGE( INDEX('ADR Tracking'!$G:$ZX, MATCH($A11, 'ADR Tracking'!$A:$A, 0), ), COLUMN()-4 ), INDEX('ADR Tracking'!$G:$ZX, MATCH($A11, 'ADR Tracking'!$A:$A, 0), ), 0 ) ), "" ) | G11: =IFERROR( INDEX('Project Assignment Check'!$G$1:$ZX$1, MATCH( LARGE( INDEX('ADR Tracking'!$G:$ZX, MATCH($A11, 'ADR Tracking'!$A:$A, 0), ), COLUMN()-4 ), INDEX('ADR Tracking'!$G:$ZX, MATCH($A11, 'ADR Tracking'!$A:$A, 0), ), 0 ) ), "" ) | H11: =IFERROR( INDEX('Project Assignment Check'!$G$1:$ZX$1, MATCH( LARGE( INDEX('ADR Tracking'!$G:$ZX, MATCH($A11, 'ADR Tracking'!$A:$A, 0), ), COLUMN()-4 ), INDEX('ADR Tracking'!$G:$ZX, MATCH($A11, 'ADR Tracking'!$A:$A, 0), ), 0 ) ), "" ) | I11: =IFERROR( INDEX('Project Assignment Check'!$G$1:$ZX$1, MATCH( LARGE( INDEX('ADR Tracking'!$G:$ZX, MATCH($A11, 'ADR Tracking'!$A:$A, 0), ), COLUMN()-4 ), INDEX('ADR Tracking'!$G:$ZX, MATCH($A11, 'ADR Tracking'!$A:$A, 0), ), 0 ) ), "" ) | J11: =IFERROR( INDEX('Project Assignment Check'!$G$1:$ZX$1, MATCH( LARGE( INDEX('ADR Tracking'!$G:$ZX, MATCH($A11, 'ADR Tracking'!$A:$A, 0), ), COLUMN()-4 ), INDEX('ADR Tracking'!$G:$ZX, MATCH($A11, 'ADR Tracking'!$A:$A, 0), ), 0 ) ), "" )
A12: SRP8-016 | B12: Battery | C12: Energy Systems | D12: Chassis & Bodywork | E12: =IFERROR( INDEX('Project Assignment Check'!$G$1:$ZX$1, MATCH( LARGE( INDEX('ADR Tracking'!$G:$ZX, MATCH($A12, 'ADR Tracking'!$A:$A, 0), ), COLUMN()-4 ), INDEX('ADR Tracking'!$G:$ZX, MATCH($A12, 'ADR Tracking'!$A:$A, 0), ), 0 ) ), "" ) -> ADR-109 | F12: =IFERROR( INDEX('Project Assignment Check'!$G$1:$ZX$1, MATCH( LARGE( INDEX('ADR Tracking'!$G:$ZX, MATCH($A12, 'ADR Tracking'!$A:$A, 0), ), COLUMN()-4 ), INDEX('ADR Tracking'!$G:$ZX, MATCH($A12, 'ADR Tracking'!$A:$A, 0), ), 0 ) ), "" ) | G12: =IFERROR( INDEX('Project Assignment Check'!$G$1:$ZX$1, MATCH( LARGE( INDEX('ADR Tracking'!$G:$ZX, MATCH($A12, 'ADR Tracking'!$A:$A, 0), ), COLUMN()-4 ), INDEX('ADR Tracking'!$G:$ZX, MATCH($A12, 'ADR Tracking'!$A:$A, 0), ), 0 ) ), "" ) | H12: =IFERROR( INDEX('Project Assignment Check'!$G$1:$ZX$1, MATCH( LARGE( INDEX('ADR Tracking'!$G:$ZX, MATCH($A12, 'ADR Tracking'!$A:$A, 0), ), COLUMN()-4 ), INDEX('ADR Tracking'!$G:$ZX, MATCH($A12, 'ADR Tracking'!$A:$A, 0), ), 0 ) ), "" ) | I12: =IFERROR( INDEX('Project Assignment Check'!$G$1:$ZX$1, MATCH( LARGE( INDEX('ADR Tracking'!$G:$ZX, MATCH($A12, 'ADR Tracking'!$A:$A, 0), ), COLUMN()-4 ), INDEX('ADR Tracking'!$G:$ZX, MATCH($A12, 'ADR Tracking'!$A:$A, 0), ), 0 ) ), "" ) | J12: =IFERROR( INDEX('Project Assignment Check'!$G$1:$ZX$1, MATCH( LARGE( INDEX('ADR Tracking'!$G:$ZX, MATCH($A12, 'ADR Tracking'!$A:$A, 0), ), COLUMN()-4 ), INDEX('ADR Tracking'!$G:$ZX, MATCH($A12, 'ADR Tracking'!$A:$A, 0), ), 0 ) ), "" )
A13: SRP8-017 | B13: Auxillary Power Distribution | C13: Energy Systems | D13: Energy Systems | E13: =IFERROR( INDEX('Project Assignment Check'!$G$1:$ZX$1, MATCH( LARGE( INDEX('ADR Tracking'!$G:$ZX, MATCH($A13, 'ADR Tracking'!$A:$A, 0), ), COLUMN()-4 ), INDEX('ADR Tracking'!$G:$ZX, MATCH($A13, 'ADR Tracking'!$A:$A, 0), ), 0 ) ), "" ) | F13: =IFERROR( INDEX('Project Assignment Check'!$G$1:$ZX$1, MATCH( LARGE( INDEX('ADR Tracking'!$G:$ZX, MATCH($A13, 'ADR Tracking'!$A:$A, 0), ), COLUMN()-4 ), INDEX('ADR Tracking'!$G:$ZX, MATCH($A13, 'ADR Tracking'!$A:$A, 0), ), 0 ) ), "" ) | G13: =IFERROR( INDEX('Project Assignment Check'!$G$1:$ZX$1, MATCH( LARGE( INDEX('ADR Tracking'!$G:$ZX, MATCH($A13, 'ADR Tracking'!$A:$A, 0), ), COLUMN()-4 ), INDEX('ADR Tracking'!$G:$ZX, MATCH($A13, 'ADR Tracking'!$A:$A, 0), ), 0 ) ), "" ) | H13: =IFERROR( INDEX('Project Assignment Check'!$G$1:$ZX$1, MATCH( LARGE( INDEX('ADR Tracking'!$G:$ZX, MATCH($A13, 'ADR Tracking'!$A:$A, 0), ), COLUMN()-4 ), INDEX('ADR Tracking'!$G:$ZX, MATCH($A13, 'ADR Tracking'!$A:$A, 0), ), 0 ) ), "" ) | I13: =IFERROR( INDEX('Project Assignment Check'!$G$1:$ZX$1, MATCH( LARGE( INDEX('ADR Tracking'!$G:$ZX, MATCH($A13, 'ADR Tracking'!$A:$A, 0), ), COLUMN()-4 ), INDEX('ADR Tracking'!$G:$ZX, MATCH($A13, 'ADR Tracking'!$A:$A, 0), ), 0 ) ), "" ) | J13: =IFERROR( INDEX('Project Assignment Check'!$G$1:$ZX$1, MATCH( LARGE( INDEX('ADR Tracking'!$G:$ZX, MATCH($A13, 'ADR Tracking'!$A:$A, 0), ), COLUMN()-4 ), INDEX('ADR Tracking'!$G:$ZX, MATCH($A13, 'ADR Tracking'!$A:$A, 0), ), 0 ) ), "" )
A14: SRP8-018 | B14: Energy Control | C14: Energy Systems | E14: =IFERROR( INDEX('Project Assignment Check'!$G$1:$ZX$1, MATCH( LARGE( INDEX('ADR Tracking'!$G:$ZX, MATCH($A14, 'ADR Tracking'!$A:$A, 0), ), COLUMN()-4 ), INDEX('ADR Tracking'!$G:$ZX, MATCH($A14, 'ADR Tracking'!$A:$A, 0), ), 0 ) ), "" ) -> ADR-90 | F14: =IFERROR( INDEX('Project Assignment Check'!$G$1:$ZX$1, MATCH( LARGE( INDEX('ADR Tracking'!$G:$ZX, MATCH($A14, 'ADR Tracking'!$A:$A, 0), ), COLUMN()-4 ), INDEX('ADR Tracking'!$G:$ZX, MATCH($A14, 'ADR Tracking'!$A:$A, 0), ), 0 ) ), "" ) -> ADR-90 | G14: =IFERROR( INDEX('Project Assignment Check'!$G$1:$ZX$1, MATCH( LARGE( INDEX('ADR Tracking'!$G:$ZX, MATCH($A14, 'ADR Tracking'!$A:$A, 0), ), COLUMN()-4 ), INDEX('ADR Tracking'!$G:$ZX, MATCH($A14, 'ADR Tracking'!$A:$A, 0), ), 0 ) ), "" ) | H14: =IFERROR( INDEX('Project Assignment Check'!$G$1:$ZX$1, MATCH( LARGE( INDEX('ADR Tracking'!$G:$ZX, MATCH($A14, 'ADR Tracking'!$A:$A, 0), ), COLUMN()-4 ), INDEX('ADR Tracking'!$G:$ZX, MATCH($A14, 'ADR Tracking'!$A:$A, 0), ), 0 ) ), "" ) | I14: =IFERROR( INDEX('Project Assignment Check'!$G$1:$ZX$1, MATCH( LARGE( INDEX('ADR Tracking'!$G:$ZX, MATCH($A14, 'ADR Tracking'!$A:$A, 0), ), COLUMN()-4 ), INDEX('ADR Tracking'!$G:$ZX, MATCH($A14, 'ADR Tracking'!$A:$A, 0), ), 0 ) ), "" ) | J14: =IFERROR( INDEX('Project Assignment Check'!$G$1:$ZX$1, MATCH( LARGE( INDEX('ADR Tracking'!$G:$ZX, MATCH($A14, 'ADR Tracking'!$A:$A, 0), ), COLUMN()-4 ), INDEX('ADR Tracking'!$G:$ZX, MATCH($A14, 'ADR Tracking'!$A:$A, 0), ), 0 ) ), "" )
A15: SRP8-019 | B15: MPPTs | C15: Energy Systems | E15: =IFERROR( INDEX('Project Assignment Check'!$G$1:$ZX$1, MATCH( LARGE( INDEX('ADR Tracking'!$G:$ZX, MATCH($A15, 'ADR Tracking'!$A:$A, 0), ), COLUMN()-4 ), INDEX('ADR Tracking'!$G:$ZX, MATCH($A15, 'ADR Tracking'!$A:$A, 0), ), 0 ) ), "" ) | F15: =IFERROR( INDEX('Project Assignment Check'!$G$1:$ZX$1, MATCH( LARGE( INDEX('ADR Tracking'!$G:$ZX, MATCH($A15, 'ADR Tracking'!$A:$A, 0), ), COLUMN()-4 ), INDEX('ADR Tracking'!$G:$ZX, MATCH($A15, 'ADR Tracking'!$A:$A, 0), ), 0 ) ), "" ) | G15: =IFERROR( INDEX('Project Assignment Check'!$G$1:$ZX$1, MATCH( LARGE( INDEX('ADR Tracking'!$G:$ZX, MATCH($A15, 'ADR Tracking'!$A:$A, 0), ), COLUMN()-4 ), INDEX('ADR Tracking'!$G:$ZX, MATCH($A15, 'ADR Tracking'!$A:$A, 0), ), 0 ) ), "" ) | H15: =IFERROR( INDEX('Project Assignment Check'!$G$1:$ZX$1, MATCH( LARGE( INDEX('ADR Tracking'!$G:$ZX, MATCH($A15, 'ADR Tracking'!$A:$A, 0), ), COLUMN()-4 ), INDEX('ADR Tracking'!$G:$ZX, MATCH($A15, 'ADR Tracking'!$A:$A, 0), ), 0 ) ), "" ) | I15: =IFERROR( INDEX('Project Assignment Check'!$G$1:$ZX$1, MATCH( LARGE( INDEX('ADR Tracking'!$G:$ZX, MATCH($A15, 'ADR Tracking'!$A:$A, 0), ), COLUMN()-4 ), INDEX('ADR Tracking'!$G:$ZX, MATCH($A15, 'ADR Tracking'!$A:$A, 0), ), 0 ) ), "" ) | J15: =IFERROR( INDEX('Project Assignment Check'!$G$1:$ZX$1, MATCH( LARGE( INDEX('ADR Tracking'!$G:$ZX, MATCH($A15, 'ADR Tracking'!$A:$A, 0), ), COLUMN()-4 ), INDEX('ADR Tracking'!$G:$ZX, MATCH($A15, 'ADR Tracking'!$A:$A, 0), ), 0 ) ), "" )
A16: SRP8-020 | B16: Solar Array | C16: Energy Systems | D16: Chassis & Bodywork | E16: =IFERROR( INDEX('Project Assignment Check'!$G$1:$ZX$1, MATCH( LARGE( INDEX('ADR Tracking'!$G:$ZX, MATCH($A16, 'ADR Tracking'!$A:$A, 0), ), COLUMN()-4 ), INDEX('ADR Tracking'!$G:$ZX, MATCH($A16, 'ADR Tracking'!$A:$A, 0), ), 0 ) ), "" ) | F16: =IFERROR( INDEX('Project Assignment Check'!$G$1:$ZX$1, MATCH( LARGE( INDEX('ADR Tracking'!$G:$ZX, MATCH($A16, 'ADR Tracking'!$A:$A, 0), ), COLUMN()-4 ), INDEX('ADR Tracking'!$G:$ZX, MATCH($A16, 'ADR Tracking'!$A:$A, 0), ), 0 ) ), "" ) | G16: =IFERROR( INDEX('Project Assignment Check'!$G$1:$ZX$1, MATCH( LARGE( INDEX('ADR Tracking'!$G:$ZX, MATCH($A16, 'ADR Tracking'!$A:$A, 0), ), COLUMN()-4 ), INDEX('ADR Tracking'!$G:$ZX, MATCH($A16, 'ADR Tracking'!$A:$A, 0), ), 0 ) ), "" ) | H16: =IFERROR( INDEX('Project Assignment Check'!$G$1:$ZX$1, MATCH( LARGE( INDEX('ADR Tracking'!$G:$ZX, MATCH($A16, 'ADR Tracking'!$A:$A, 0), ), COLUMN()-4 ), INDEX('ADR Tracking'!$G:$ZX, MATCH($A16, 'ADR Tracking'!$A:$A, 0), ), 0 ) ), "" ) | I16: =IFERROR( INDEX('Project Assignment Check'!$G$1:$ZX$1, MATCH( LARGE( INDEX('ADR Tracking'!$G:$ZX, MATCH($A16, 'ADR Tracking'!$A:$A, 0), ), COLUMN()-4 ), INDEX('ADR Tracking'!$G:$ZX, MATCH($A16, 'ADR Tracking'!$A:$A, 0), ), 0 ) ), "" ) | J16: =IFERROR( INDEX('Project Assignment Check'!$G$1:$ZX$1, MATCH( LARGE( INDEX('ADR Tracking'!$G:$ZX, MATCH($A16, 'ADR Tracking'!$A:$A, 0), ), COLUMN()-4 ), INDEX('ADR Tracking'!$G:$ZX, MATCH($A16, 'ADR Tracking'!$A:$A, 0), ), 0 ) ), "" )
A17: SRP8-021 | B17: Charging | C17: Energy Systems | D17: Chassis & Bodywork | E17: =IFERROR( INDEX('Project Assignment Check'!$G$1:$ZX$1, MATCH( LARGE( INDEX('ADR Tracking'!$G:$ZX, MATCH($A17, 'ADR Tracking'!$A:$A, 0), ), COLUMN()-4 ), INDEX('ADR Tracking'!$G:$ZX, MATCH($A17, 'ADR Tracking'!$A:$A, 0), ), 0 ) ), "" ) -> ADR-109 | F17: =IFERROR( INDEX('Project Assignment Check'!$G$1:$ZX$1, MATCH( LARGE( INDEX('ADR Tracking'!$G:$ZX, MATCH($A17, 'ADR Tracking'!$A:$A, 0), ), COLUMN()-4 ), INDEX('ADR Tracking'!$G:$ZX, MATCH($A17, 'ADR Tracking'!$A:$A, 0), ), 0 ) ), "" ) | G17: =IFERROR( INDEX('Project Assignment Check'!$G$1:$ZX$1, MATCH( LARGE( INDEX('ADR Tracking'!$G:$ZX, MATCH($A17, 'ADR Tracking'!$A:$A, 0), ), COLUMN()-4 ), INDEX('ADR Tracking'!$G:$ZX, MATCH($A17, 'ADR Tracking'!$A:$A, 0), ), 0 ) ), "" ) | H17: =IFERROR( INDEX('Project Assignment Check'!$G$1:$ZX$1, MATCH( LARGE( INDEX('ADR Tracking'!$G:$ZX, MATCH($A17, 'ADR Tracking'!$A:$A, 0), ), COLUMN()-4 ), INDEX('ADR Tracking'!$G:$ZX, MATCH($A17, 'ADR Tracking'!$A:$A, 0), ), 0 ) ), "" ) | I17: =IFERROR( INDEX('Project Assignment Check'!$G$1:$ZX$1, MATCH( LARGE( INDEX('ADR Tracking'!$G:$ZX, MATCH($A17, 'ADR Tracking'!$A:$A, 0), ), COLUMN()-4 ), INDEX('ADR Tracking'!$G:$ZX, MATCH($A17, 'ADR Tracking'!$A:$A, 0), ), 0 ) ), "" ) | J17: =IFERROR( INDEX('Project Assignment Check'!$G$1:$ZX$1, MATCH( LARGE( INDEX('ADR Tracking'!$G:$ZX, MATCH($A17, 'ADR Tracking'!$A:$A, 0), ), COLUMN()-4 ), INDEX('ADR Tracking'!$G:$ZX, MATCH($A17, 'ADR Tracking'!$A:$A, 0), ), 0 ) ), "" )
A18: SRP8-022 | B18: Steering Wheel | C18: Interior | D18: Embedded Systems | E18: =IFERROR( INDEX('Project Assignment Check'!$G$1:$ZX$1, MATCH( LARGE( INDEX('ADR Tracking'!$G:$ZX, MATCH($A18, 'ADR Tracking'!$A:$A, 0), ), COLUMN()-4 ), INDEX('ADR Tracking'!$G:$ZX, MATCH($A18, 'ADR Tracking'!$A:$A, 0), ), 0 ) ), "" ) -> ADR-10 | F18: =IFERROR( INDEX('Project Assignment Check'!$G$1:$ZX$1, MATCH( LARGE( INDEX('ADR Tracking'!$G:$ZX, MATCH($A18, 'ADR Tracking'!$A:$A, 0), ), COLUMN()-4 ), INDEX('ADR Tracking'!$G:$ZX, MATCH($A18, 'ADR Tracking'!$A:$A, 0), ), 0 ) ), "" ) -> ADR-10 | G18: =IFERROR( INDEX('Project Assignment Check'!$G$1:$ZX$1, MATCH( LARGE( INDEX('ADR Tracking'!$G:$ZX, MATCH($A18, 'ADR Tracking'!$A:$A, 0), ), COLUMN()-4 ), INDEX('ADR Tracking'!$G:$ZX, MATCH($A18, 'ADR Tracking'!$A:$A, 0), ), 0 ) ), "" ) -> ADR-93 | H18: =IFERROR( INDEX('Project Assignment Check'!$G$1:$ZX$1, MATCH( LARGE( INDEX('ADR Tracking'!$G:$ZX, MATCH($A18, 'ADR Tracking'!$A:$A, 0), ), COLUMN()-4 ), INDEX('ADR Tracking'!$G:$ZX, MATCH($A18, 'ADR Tracking'!$A:$A, 0), ), 0 ) ), "" ) | I18: =IFERROR( INDEX('Project Assignment Check'!$G$1:$ZX$1, MATCH( LARGE( INDEX('ADR Tracking'!$G:$ZX, MATCH($A18, 'ADR Tracking'!$A:$A, 0), ), COLUMN()-4 ), INDEX('ADR Tracking'!$G:$ZX, MATCH($A18, 'ADR Tracking'!$A:$A, 0), ), 0 ) ), "" ) | J18: =IFERROR( INDEX('Project Assignment Check'!$G$1:$ZX$1, MATCH( LARGE( INDEX('ADR Tracking'!$G:$ZX, MATCH($A18, 'ADR Tracking'!$A:$A, 0), ), COLUMN()-4 ), INDEX('ADR Tracking'!$G:$ZX, MATCH($A18, 'ADR Tracking'!$A:$A, 0), ), 0 ) ), "" )
A19: SRP8-023 | B19: Interior Lights | C19: Interior | D19: Embedded Systems | E19: =IFERROR( INDEX('Project Assignment Check'!$G$1:$ZX$1, MATCH( LARGE( INDEX('ADR Tracking'!$G:$ZX, MATCH($A19, 'ADR Tracking'!$A:$A, 0), ), COLUMN()-4 ), INDEX('ADR Tracking'!$G:$ZX, MATCH($A19, 'ADR Tracking'!$A:$A, 0), ), 0 ) ), "" ) | F19: =IFERROR( INDEX('Project Assignment Check'!$G$1:$ZX$1, MATCH( LARGE( INDEX('ADR Tracking'!$G:$ZX, MATCH($A19, 'ADR Tracking'!$A:$A, 0), ), COLUMN()-4 ), INDEX('ADR Tracking'!$G:$ZX, MATCH($A19, 'ADR Tracking'!$A:$A, 0), ), 0 ) ), "" ) | G19: =IFERROR( INDEX('Project Assignment Check'!$G$1:$ZX$1, MATCH( LARGE( INDEX('ADR Tracking'!$G:$ZX, MATCH($A19, 'ADR Tracking'!$A:$A, 0), ), COLUMN()-4 ), INDEX('ADR Tracking'!$G:$ZX, MATCH($A19, 'ADR Tracking'!$A:$A, 0), ), 0 ) ), "" ) | H19: =IFERROR( INDEX('Project Assignment Check'!$G$1:$ZX$1, MATCH( LARGE( INDEX('ADR Tracking'!$G:$ZX, MATCH($A19, 'ADR Tracking'!$A:$A, 0), ), COLUMN()-4 ), INDEX('ADR Tracking'!$G:$ZX, MATCH($A19, 'ADR Tracking'!$A:$A, 0), ), 0 ) ), "" ) | I19: =IFERROR( INDEX('Project Assignment Check'!$G$1:$ZX$1, MATCH( LARGE( INDEX('ADR Tracking'!$G:$ZX, MATCH($A19, 'ADR Tracking'!$A:$A, 0), ), COLUMN()-4 ), INDEX('ADR Tracking'!$G:$ZX, MATCH($A19, 'ADR Tracking'!$A:$A, 0), ), 0 ) ), "" ) | J19: =IFERROR( INDEX('Project Assignment Check'!$G$1:$ZX$1, MATCH( LARGE( INDEX('ADR Tracking'!$G:$ZX, MATCH($A19, 'ADR Tracking'!$A:$A, 0), ), COLUMN()-4 ), INDEX('ADR Tracking'!$G:$ZX, MATCH($A19, 'ADR Tracking'!$A:$A, 0), ), 0 ) ), "" )
A20: SRP8-024 | B20: Rear Vision System | C20: Interior | D20: Chassis & Bodywork | E20: =IFERROR( INDEX('Project Assignment Check'!$G$1:$ZX$1, MATCH( LARGE( INDEX('ADR Tracking'!$G:$ZX, MATCH($A20, 'ADR Tracking'!$A:$A, 0), ), COLUMN()-4 ), INDEX('ADR Tracking'!$G:$ZX, MATCH($A20, 'ADR Tracking'!$A:$A, 0), ), 0 ) ), "" ) -> ADR-14 | F20: =IFERROR( INDEX('Project Assignment Check'!$G$1:$ZX$1, MATCH( LARGE( INDEX('ADR Tracking'!$G:$ZX, MATCH($A20, 'ADR Tracking'!$A:$A, 0), ), COLUMN()-4 ), INDEX('ADR Tracking'!$G:$ZX, MATCH($A20, 'ADR Tracking'!$A:$A, 0), ), 0 ) ), "" ) | G20: =IFERROR( INDEX('Project Assignment Check'!$G$1:$ZX$1, MATCH( LARGE( INDEX('ADR Tracking'!$G:$ZX, MATCH($A20, 'ADR Tracking'!$A:$A, 0), ), COLUMN()-4 ), INDEX('ADR Tracking'!$G:$ZX, MATCH($A20, 'ADR Tracking'!$A:$A, 0), ), 0 ) ), "" ) | H20: =IFERROR( INDEX('Project Assignment Check'!$G$1:$ZX$1, MATCH( LARGE( INDEX('ADR Tracking'!$G:$ZX, MATCH($A20, 'ADR Tracking'!$A:$A, 0), ), COLUMN()-4 ), INDEX('ADR Tracking'!$G:$ZX, MATCH($A20, 'ADR Tracking'!$A:$A, 0), ), 0 ) ), "" ) | I20: =IFERROR( INDEX('Project Assignment Check'!$G$1:$ZX$1, MATCH( LARGE( INDEX('ADR Tracking'!$G:$ZX, MATCH($A20, 'ADR Tracking'!$A:$A, 0), ), COLUMN()-4 ), INDEX('ADR Tracking'!$G:$ZX, MATCH($A20, 'ADR Tracking'!$A:$A, 0), ), 0 ) ), "" ) | J20: =IFERROR( INDEX('Project Assignment Check'!$G$1:$ZX$1, MATCH( LARGE( INDEX('ADR Tracking'!$G:$ZX, MATCH($A20, 'ADR Tracking'!$A:$A, 0), ), COLUMN()-4 ), INDEX('ADR Tracking'!$G:$ZX, MATCH($A20, 'ADR Tracking'!$A:$A, 0), ), 0 ) ), "" )
A21: SRP8-025 | B21: Side Vision System | C21: Interior | D21: Chassis & Bodywork | E21: =IFERROR( INDEX('Project Assignment Check'!$G$1:$ZX$1, MATCH( LARGE( INDEX('ADR Tracking'!$G:$ZX, MATCH($A21, 'ADR Tracking'!$A:$A, 0), ), COLUMN()-4 ), INDEX('ADR Tracking'!$G:$ZX, MATCH($A21, 'ADR Tracking'!$A:$A, 0), ), 0 ) ), "" ) | F21: =IFERROR( INDEX('Project Assignment Check'!$G$1:$ZX$1, MATCH( LARGE( INDEX('ADR Tracking'!$G:$ZX, MATCH($A21, 'ADR Tracking'!$A:$A, 0), ), COLUMN()-4 ), INDEX('ADR Tracking'!$G:$ZX, MATCH($A21, 'ADR Tracking'!$A:$A, 0), ), 0 ) ), "" ) | G21: =IFERROR( INDEX('Project Assignment Check'!$G$1:$ZX$1, MATCH( LARGE( INDEX('ADR Tracking'!$G:$ZX, MATCH($A21, 'ADR Tracking'!$A:$A, 0), ), COLUMN()-4 ), INDEX('ADR Tracking'!$G:$ZX, MATCH($A21, 'ADR Tracking'!$A:$A, 0), ), 0 ) ), "" ) | H21: =IFERROR( INDEX('Project Assignment Check'!$G$1:$ZX$1, MATCH( LARGE( INDEX('ADR Tracking'!$G:$ZX, MATCH($A21, 'ADR Tracking'!$A:$A, 0), ), COLUMN()-4 ), INDEX('ADR Tracking'!$G:$ZX, MATCH($A21, 'ADR Tracking'!$A:$A, 0), ), 0 ) ), "" ) | I21: =IFERROR( INDEX('Project Assignment Check'!$G$1:$ZX$1, MATCH( LARGE( INDEX('ADR Tracking'!$G:$ZX, MATCH($A21, 'ADR Tracking'!$A:$A, 0), ), COLUMN()-4 ), INDEX('ADR Tracking'!$G:$ZX, MATCH($A21, 'ADR Tracking'!$A:$A, 0), ), 0 ) ), "" ) | J21: =IFERROR( INDEX('Project Assignment Check'!$G$1:$ZX$1, MATCH( LARGE( INDEX('ADR Tracking'!$G:$ZX, MATCH($A21, 'ADR Tracking'!$A:$A, 0), ), COLUMN()-4 ), INDEX('ADR Tracking'!$G:$ZX, MATCH($A21, 'ADR Tracking'!$A:$A, 0), ), 0 ) ), "" )
A22: SRP8-026 | B22: Pedals | C22: Interior | E22: =IFERROR( INDEX('Project Assignment Check'!$G$1:$ZX$1, MATCH( LARGE( INDEX('ADR Tracking'!$G:$ZX, MATCH($A22, 'ADR Tracking'!$A:$A, 0), ), COLUMN()-4 ), INDEX('ADR Tracking'!$G:$ZX, MATCH($A22, 'ADR Tracking'!$A:$A, 0), ), 0 ) ), "" ) -> ADR-31 | F22: =IFERROR( INDEX('Project Assignment Check'!$G$1:$ZX$1, MATCH( LARGE( INDEX('ADR Tracking'!$G:$ZX, MATCH($A22, 'ADR Tracking'!$A:$A, 0), ), COLUMN()-4 ), INDEX('ADR Tracking'!$G:$ZX, MATCH($A22, 'ADR Tracking'!$A:$A, 0), ), 0 ) ), "" ) | G22: =IFERROR( INDEX('Project Assignment Check'!$G$1:$ZX$1, MATCH( LARGE( INDEX('ADR Tracking'!$G:$ZX, MATCH($A22, 'ADR Tracking'!$A:$A, 0), ), COLUMN()-4 ), INDEX('ADR Tracking'!$G:$ZX, MATCH($A22, 'ADR Tracking'!$A:$A, 0), ), 0 ) ), "" ) | H22: =IFERROR( INDEX('Project Assignment Check'!$G$1:$ZX$1, MATCH( LARGE( INDEX('ADR Tracking'!$G:$ZX, MATCH($A22, 'ADR Tracking'!$A:$A, 0), ), COLUMN()-4 ), INDEX('ADR Tracking'!$G:$ZX, MATCH($A22, 'ADR Tracking'!$A:$A, 0), ), 0 ) ), "" ) | I22: =IFERROR( INDEX('Project Assignment Check'!$G$1:$ZX$1, MATCH( LARGE( INDEX('ADR Tracking'!$G:$ZX, MATCH($A22, 'ADR Tracking'!$A:$A, 0), ), COLUMN()-4 ), INDEX('ADR Tracking'!$G:$ZX, MATCH($A22, 'ADR Tracking'!$A:$A, 0), ), 0 ) ), "" ) | J22: =IFERROR( INDEX('Project Assignment Check'!$G$1:$ZX$1, MATCH( LARGE( INDEX('ADR Tracking'!$G:$ZX, MATCH($A22, 'ADR Tracking'!$A:$A, 0), ), COLUMN()-4 ), INDEX('ADR Tracking'!$G:$ZX, MATCH($A22, 'ADR Tracking'!$A:$A, 0), ), 0 ) ), "" )
A23: SRP8-027 | B23: Ceiling | C23: Interior | D23: Chassis & Bodywork | E23: =IFERROR( INDEX('Project Assignment Check'!$G$1:$ZX$1, MATCH( LARGE( INDEX('ADR Tracking'!$G:$ZX, MATCH($A23, 'ADR Tracking'!$A:$A, 0), ), COLUMN()-4 ), INDEX('ADR Tracking'!$G:$ZX, MATCH($A23, 'ADR Tracking'!$A:$A, 0), ), 0 ) ), "" ) -> ADR-11 | F23: =IFERROR( INDEX('Project Assignment Check'!$G$1:$ZX$1, MATCH( LARGE( INDEX('ADR Tracking'!$G:$ZX, MATCH($A23, 'ADR Tracking'!$A:$A, 0), ), COLUMN()-4 ), INDEX('ADR Tracking'!$G:$ZX, MATCH($A23, 'ADR Tracking'!$A:$A, 0), ), 0 ) ), "" ) -> ADR-21 | G23: =IFERROR( INDEX('Project Assignment Check'!$G$1:$ZX$1, MATCH( LARGE( INDEX('ADR Tracking'!$G:$ZX, MATCH($A23, 'ADR Tracking'!$A:$A, 0), ), COLUMN()-4 ), INDEX('ADR Tracking'!$G:$ZX, MATCH($A23, 'ADR Tracking'!$A:$A, 0), ), 0 ) ), "" ) -> ADR-42 | H23: =IFERROR( INDEX('Project Assignment Check'!$G$1:$ZX$1, MATCH( LARGE( INDEX('ADR Tracking'!$G:$ZX, MATCH($A23, 'ADR Tracking'!$A:$A, 0), ), COLUMN()-4 ), INDEX('ADR Tracking'!$G:$ZX, MATCH($A23, 'ADR Tracking'!$A:$A, 0), ), 0 ) ), "" ) | I23: =IFERROR( INDEX('Project Assignment Check'!$G$1:$ZX$1, MATCH( LARGE( INDEX('ADR Tracking'!$G:$ZX, MATCH($A23, 'ADR Tracking'!$A:$A, 0), ), COLUMN()-4 ), INDEX('ADR Tracking'!$G:$ZX, MATCH($A23, 'ADR Tracking'!$A:$A, 0), ), 0 ) ), "" ) | J23: =IFERROR( INDEX('Project Assignment Check'!$G$1:$ZX$1, MATCH( LARGE( INDEX('ADR Tracking'!$G:$ZX, MATCH($A23, 'ADR Tracking'!$A:$A, 0), ), COLUMN()-4 ), INDEX('ADR Tracking'!$G:$ZX, MATCH($A23, 'ADR Tracking'!$A:$A, 0), ), 0 ) ), "" )
A24: SRP8-028 | B24: Central Display | C24: Interior | D24: Chassis & Bodywork | E24: =IFERROR( INDEX('Project Assignment Check'!$G$1:$ZX$1, MATCH( LARGE( INDEX('ADR Tracking'!$G:$ZX, MATCH($A24, 'ADR Tracking'!$A:$A, 0), ), COLUMN()-4 ), INDEX('ADR Tracking'!$G:$ZX, MATCH($A24, 'ADR Tracking'!$A:$A, 0), ), 0 ) ), "" ) -> ADR-42 | F24: =IFERROR( INDEX('Project Assignment Check'!$G$1:$ZX$1, MATCH( LARGE( INDEX('ADR Tracking'!$G:$ZX, MATCH($A24, 'ADR Tracking'!$A:$A, 0), ), COLUMN()-4 ), INDEX('ADR Tracking'!$G:$ZX, MATCH($A24, 'ADR Tracking'!$A:$A, 0), ), 0 ) ), "" ) -> ADR-21 | G24: =IFERROR( INDEX('Project Assignment Check'!$G$1:$ZX$1, MATCH( LARGE( INDEX('ADR Tracking'!$G:$ZX, MATCH($A24, 'ADR Tracking'!$A:$A, 0), ), COLUMN()-4 ), INDEX('ADR Tracking'!$G:$ZX, MATCH($A24, 'ADR Tracking'!$A:$A, 0), ), 0 ) ), "" ) | H24: =IFERROR( INDEX('Project Assignment Check'!$G$1:$ZX$1, MATCH( LARGE( INDEX('ADR Tracking'!$G:$ZX, MATCH($A24, 'ADR Tracking'!$A:$A, 0), ), COLUMN()-4 ), INDEX('ADR Tracking'!$G:$ZX, MATCH($A24, 'ADR Tracking'!$A:$A, 0), ), 0 ) ), "" ) | I24: =IFERROR( INDEX('Project Assignment Check'!$G$1:$ZX$1, MATCH( LARGE( INDEX('ADR Tracking'!$G:$ZX, MATCH($A24, 'ADR Tracking'!$A:$A, 0), ), COLUMN()-4 ), INDEX('ADR Tracking'!$G:$ZX, MATCH($A24, 'ADR Tracking'!$A:$A, 0), ), 0 ) ), "" ) | J24: =IFERROR( INDEX('Project Assignment Check'!$G$1:$ZX$1, MATCH( LARGE( INDEX('ADR Tracking'!$G:$ZX, MATCH($A24, 'ADR Tracking'!$A:$A, 0), ), COLUMN()-4 ), INDEX('ADR Tracking'!$G:$ZX, MATCH($A24, 'ADR Tracking'!$A:$A, 0), ), 0 ) ), "" )
A25: SRP8-029 | B25: Driver Display | C25: Interior | D25: Embedded Systems | E25: =IFERROR( INDEX('Project Assignment Check'!$G$1:$ZX$1, MATCH( LARGE( INDEX('ADR Tracking'!$G:$ZX, MATCH($A25, 'ADR Tracking'!$A:$A, 0), ), COLUMN()-4 ), INDEX('ADR Tracking'!$G:$ZX, MATCH($A25, 'ADR Tracking'!$A:$A, 0), ), 0 ) ), "" ) -> ADR-42 | F25: =IFERROR( INDEX('Project Assignment Check'!$G$1:$ZX$1, MATCH( LARGE( INDEX('ADR Tracking'!$G:$ZX, MATCH($A25, 'ADR Tracking'!$A:$A, 0), ), COLUMN()-4 ), INDEX('ADR Tracking'!$G:$ZX, MATCH($A25, 'ADR Tracking'!$A:$A, 0), ), 0 ) ), "" ) -> ADR-18 | G25: =IFERROR( INDEX('Project Assignment Check'!$G$1:$ZX$1, MATCH( LARGE( INDEX('ADR Tracking'!$G:$ZX, MATCH($A25, 'ADR Tracking'!$A:$A, 0), ), COLUMN()-4 ), INDEX('ADR Tracking'!$G:$ZX, MATCH($A25, 'ADR Tracking'!$A:$A, 0), ), 0 ) ), "" ) -> ADR-18 | H25: =IFERROR( INDEX('Project Assignment Check'!$G$1:$ZX$1, MATCH( LARGE( INDEX('ADR Tracking'!$G:$ZX, MATCH($A25, 'ADR Tracking'!$A:$A, 0), ), COLUMN()-4 ), INDEX('ADR Tracking'!$G:$ZX, MATCH($A25, 'ADR Tracking'!$A:$A, 0), ), 0 ) ), "" ) -> ADR-31 | I25: =IFERROR( INDEX('Project Assignment Check'!$G$1:$ZX$1, MATCH( LARGE( INDEX('ADR Tracking'!$G:$ZX, MATCH($A25, 'ADR Tracking'!$A:$A, 0), ), COLUMN()-4 ), INDEX('ADR Tracking'!$G:$ZX, MATCH($A25, 'ADR Tracking'!$A:$A, 0), ), 0 ) ), "" ) -> ADR-90 | J25: =IFERROR( INDEX('Project Assignment Check'!$G$1:$ZX$1, MATCH( LARGE( INDEX('ADR Tracking'!$G:$ZX, MATCH($A25, 'ADR Tracking'!$A:$A, 0), ), COLUMN()-4 ), INDEX('ADR Tracking'!$G:$ZX, MATCH($A25, 'ADR Tracking'!$A:$A, 0), ), 0 ) ), "" ) -> ADR-90
A26: SRP8-032 | B26: Front Seats | C26: Interior | E26: =IFERROR( INDEX('Project Assignment Check'!$G$1:$ZX$1, MATCH( LARGE( INDEX('ADR Tracking'!$G:$ZX, MATCH($A26, 'ADR Tracking'!$A:$A, 0), ), COLUMN()-4 ), INDEX('ADR Tracking'!$G:$ZX, MATCH($A26, 'ADR Tracking'!$A:$A, 0), ), 0 ) ), "" ) -> ADR-03 | F26: =IFERROR( INDEX('Project Assignment Check'!$G$1:$ZX$1, MATCH( LARGE( INDEX('ADR Tracking'!$G:$ZX, MATCH($A26, 'ADR Tracking'!$A:$A, 0), ), COLUMN()-4 ), INDEX('ADR Tracking'!$G:$ZX, MATCH($A26, 'ADR Tracking'!$A:$A, 0), ), 0 ) ), "" ) -> ADR-21 | G26: =IFERROR( INDEX('Project Assignment Check'!$G$1:$ZX$1, MATCH( LARGE( INDEX('ADR Tracking'!$G:$ZX, MATCH($A26, 'ADR Tracking'!$A:$A, 0), ), COLUMN()-4 ), INDEX('ADR Tracking'!$G:$ZX, MATCH($A26, 'ADR Tracking'!$A:$A, 0), ), 0 ) ), "" ) -> ADR-42 | H26: =IFERROR( INDEX('Project Assignment Check'!$G$1:$ZX$1, MATCH( LARGE( INDEX('ADR Tracking'!$G:$ZX, MATCH($A26, 'ADR Tracking'!$A:$A, 0), ), COLUMN()-4 ), INDEX('ADR Tracking'!$G:$ZX, MATCH($A26, 'ADR Tracking'!$A:$A, 0), ), 0 ) ), "" ) -> ADR-42 | I26: =IFERROR( INDEX('Project Assignment Check'!$G$1:$ZX$1, MATCH( LARGE( INDEX('ADR Tracking'!$G:$ZX, MATCH($A26, 'ADR Tracking'!$A:$A, 0), ), COLUMN()-4 ), INDEX('ADR Tracking'!$G:$ZX, MATCH($A26, 'ADR Tracking'!$A:$A, 0), ), 0 ) ), "" ) | J26: =IFERROR( INDEX('Project Assignment Check'!$G$1:$ZX$1, MATCH( LARGE( INDEX('ADR Tracking'!$G:$ZX, MATCH($A26, 'ADR Tracking'!$A:$A, 0), ), COLUMN()-4 ), INDEX('ADR Tracking'!$G:$ZX, MATCH($A26, 'ADR Tracking'!$A:$A, 0), ), 0 ) ), "" )
A27: SRP8-034 | B27: Front Seatbelts | C27: Interior | E27: =IFERROR( INDEX('Project Assignment Check'!$G$1:$ZX$1, MATCH( LARGE( INDEX('ADR Tracking'!$G:$ZX, MATCH($A27, 'ADR Tracking'!$A:$A, 0), ), COLUMN()-4 ), INDEX('ADR Tracking'!$G:$ZX, MATCH($A27, 'ADR Tracking'!$A:$A, 0), ), 0 ) ), "" ) -> ADR-04 | F27: =IFERROR( INDEX('Project Assignment Check'!$G$1:$ZX$1, MATCH( LARGE( INDEX('ADR Tracking'!$G:$ZX, MATCH($A27, 'ADR Tracking'!$A:$A, 0), ), COLUMN()-4 ), INDEX('ADR Tracking'!$G:$ZX, MATCH($A27, 'ADR Tracking'!$A:$A, 0), ), 0 ) ), "" ) -> ADR-05 | G27: =IFERROR( INDEX('Project Assignment Check'!$G$1:$ZX$1, MATCH( LARGE( INDEX('ADR Tracking'!$G:$ZX, MATCH($A27, 'ADR Tracking'!$A:$A, 0), ), COLUMN()-4 ), INDEX('ADR Tracking'!$G:$ZX, MATCH($A27, 'ADR Tracking'!$A:$A, 0), ), 0 ) ), "" ) -> ADR-69 | H27: =IFERROR( INDEX('Project Assignment Check'!$G$1:$ZX$1, MATCH( LARGE( INDEX('ADR Tracking'!$G:$ZX, MATCH($A27, 'ADR Tracking'!$A:$A, 0), ), COLUMN()-4 ), INDEX('ADR Tracking'!$G:$ZX, MATCH($A27, 'ADR Tracking'!$A:$A, 0), ), 0 ) ), "" ) -> ADR-42 | I27: =IFERROR( INDEX('Project Assignment Check'!$G$1:$ZX$1, MATCH( LARGE( INDEX('ADR Tracking'!$G:$ZX, MATCH($A27, 'ADR Tracking'!$A:$A, 0), ), COLUMN()-4 ), INDEX('ADR Tracking'!$G:$ZX, MATCH($A27, 'ADR Tracking'!$A:$A, 0), ), 0 ) ), "" ) | J27: =IFERROR( INDEX('Project Assignment Check'!$G$1:$ZX$1, MATCH( LARGE( INDEX('ADR Tracking'!$G:$ZX, MATCH($A27, 'ADR Tracking'!$A:$A, 0), ), COLUMN()-4 ), INDEX('ADR Tracking'!$G:$ZX, MATCH($A27, 'ADR Tracking'!$A:$A, 0), ), 0 ) ), "" )
A28: SRP8-036 | B28: Front Seat Mount | C28: Interior | E28: =IFERROR( INDEX('Project Assignment Check'!$G$1:$ZX$1, MATCH( LARGE( INDEX('ADR Tracking'!$G:$ZX, MATCH($A28, 'ADR Tracking'!$A:$A, 0), ), COLUMN()-4 ), INDEX('ADR Tracking'!$G:$ZX, MATCH($A28, 'ADR Tracking'!$A:$A, 0), ), 0 ) ), "" ) -> ADR-03 | F28: =IFERROR( INDEX('Project Assignment Check'!$G$1:$ZX$1, MATCH( LARGE( INDEX('ADR Tracking'!$G:$ZX, MATCH($A28, 'ADR Tracking'!$A:$A, 0), ), COLUMN()-4 ), INDEX('ADR Tracking'!$G:$ZX, MATCH($A28, 'ADR Tracking'!$A:$A, 0), ), 0 ) ), "" ) -> ADR-42 | G28: =IFERROR( INDEX('Project Assignment Check'!$G$1:$ZX$1, MATCH( LARGE( INDEX('ADR Tracking'!$G:$ZX, MATCH($A28, 'ADR Tracking'!$A:$A, 0), ), COLUMN()-4 ), INDEX('ADR Tracking'!$G:$ZX, MATCH($A28, 'ADR Tracking'!$A:$A, 0), ), 0 ) ), "" ) | H28: =IFERROR( INDEX('Project Assignment Check'!$G$1:$ZX$1, MATCH( LARGE( INDEX('ADR Tracking'!$G:$ZX, MATCH($A28, 'ADR Tracking'!$A:$A, 0), ), COLUMN()-4 ), INDEX('ADR Tracking'!$G:$ZX, MATCH($A28, 'ADR Tracking'!$A:$A, 0), ), 0 ) ), "" ) | I28: =IFERROR( INDEX('Project Assignment Check'!$G$1:$ZX$1, MATCH( LARGE( INDEX('ADR Tracking'!$G:$ZX, MATCH($A28, 'ADR Tracking'!$A:$A, 0), ), COLUMN()-4 ), INDEX('ADR Tracking'!$G:$ZX, MATCH($A28, 'ADR Tracking'!$A:$A, 0), ), 0 ) ), "" ) | J28: =IFERROR( INDEX('Project Assignment Check'!$G$1:$ZX$1, MATCH( LARGE( INDEX('ADR Tracking'!$G:$ZX, MATCH($A28, 'ADR Tracking'!$A:$A, 0), ), COLUMN()-4 ), INDEX('ADR Tracking'!$G:$ZX, MATCH($A28, 'ADR Tracking'!$A:$A, 0), ), 0 ) ), "" )
A29: SRP8-037 | B29: Dashboard | C29: Interior | E29: =IFERROR( INDEX('Project Assignment Check'!$G$1:$ZX$1, MATCH( LARGE( INDEX('ADR Tracking'!$G:$ZX, MATCH($A29, 'ADR Tracking'!$A:$A, 0), ), COLUMN()-4 ), INDEX('ADR Tracking'!$G:$ZX, MATCH($A29, 'ADR Tracking'!$A:$A, 0), ), 0 ) ), "" ) -> ADR-21 | F29: =IFERROR( INDEX('Project Assignment Check'!$G$1:$ZX$1, MATCH( LARGE( INDEX('ADR Tracking'!$G:$ZX, MATCH($A29, 'ADR Tracking'!$A:$A, 0), ), COLUMN()-4 ), INDEX('ADR Tracking'!$G:$ZX, MATCH($A29, 'ADR Tracking'!$A:$A, 0), ), 0 ) ), "" ) | G29: =IFERROR( INDEX('Project Assignment Check'!$G$1:$ZX$1, MATCH( LARGE( INDEX('ADR Tracking'!$G:$ZX, MATCH($A29, 'ADR Tracking'!$A:$A, 0), ), COLUMN()-4 ), INDEX('ADR Tracking'!$G:$ZX, MATCH($A29, 'ADR Tracking'!$A:$A, 0), ), 0 ) ), "" ) | H29: =IFERROR( INDEX('Project Assignment Check'!$G$1:$ZX$1, MATCH( LARGE( INDEX('ADR Tracking'!$G:$ZX, MATCH($A29, 'ADR Tracking'!$A:$A, 0), ), COLUMN()-4 ), INDEX('ADR Tracking'!$G:$ZX, MATCH($A29, 'ADR Tracking'!$A:$A, 0), ), 0 ) ), "" ) | I29: =IFERROR( INDEX('Project Assignment Check'!$G$1:$ZX$1, MATCH( LARGE( INDEX('ADR Tracking'!$G:$ZX, MATCH($A29, 'ADR Tracking'!$A:$A, 0), ), COLUMN()-4 ), INDEX('ADR Tracking'!$G:$ZX, MATCH($A29, 'ADR Tracking'!$A:$A, 0), ), 0 ) ), "" ) | J29: =IFERROR( INDEX('Project Assignment Check'!$G$1:$ZX$1, MATCH( LARGE( INDEX('ADR Tracking'!$G:$ZX, MATCH($A29, 'ADR Tracking'!$A:$A, 0), ), COLUMN()-4 ), INDEX('ADR Tracking'!$G:$ZX, MATCH($A29, 'ADR Tracking'!$A:$A, 0), ), 0 ) ), "" )
A30: SRP8-038 | B30: Motors | C30: Powertrain | D30: Chassis & Bodywork | E30: =IFERROR( INDEX('Project Assignment Check'!$G$1:$ZX$1, MATCH( LARGE( INDEX('ADR Tracking'!$G:$ZX, MATCH($A30, 'ADR Tracking'!$A:$A, 0), ), COLUMN()-4 ), INDEX('ADR Tracking'!$G:$ZX, MATCH($A30, 'ADR Tracking'!$A:$A, 0), ), 0 ) ), "" ) | F30: =IFERROR( INDEX('Project Assignment Check'!$G$1:$ZX$1, MATCH( LARGE( INDEX('ADR Tracking'!$G:$ZX, MATCH($A30, 'ADR Tracking'!$A:$A, 0), ), COLUMN()-4 ), INDEX('ADR Tracking'!$G:$ZX, MATCH($A30, 'ADR Tracking'!$A:$A, 0), ), 0 ) ), "" ) | G30: =IFERROR( INDEX('Project Assignment Check'!$G$1:$ZX$1, MATCH( LARGE( INDEX('ADR Tracking'!$G:$ZX, MATCH($A30, 'ADR Tracking'!$A:$A, 0), ), COLUMN()-4 ), INDEX('ADR Tracking'!$G:$ZX, MATCH($A30, 'ADR Tracking'!$A:$A, 0), ), 0 ) ), "" ) | H30: =IFERROR( INDEX('Project Assignment Check'!$G$1:$ZX$1, MATCH( LARGE( INDEX('ADR Tracking'!$G:$ZX, MATCH($A30, 'ADR Tracking'!$A:$A, 0), ), COLUMN()-4 ), INDEX('ADR Tracking'!$G:$ZX, MATCH($A30, 'ADR Tracking'!$A:$A, 0), ), 0 ) ), "" ) | I30: =IFERROR( INDEX('Project Assignment Check'!$G$1:$ZX$1, MATCH( LARGE( INDEX('ADR Tracking'!$G:$ZX, MATCH($A30, 'ADR Tracking'!$A:$A, 0), ), COLUMN()-4 ), INDEX('ADR Tracking'!$G:$ZX, MATCH($A30, 'ADR Tracking'!$A:$A, 0), ), 0 ) ), "" ) | J30: =IFERROR( INDEX('Project Assignment Check'!$G$1:$ZX$1, MATCH( LARGE( INDEX('ADR Tracking'!$G:$ZX, MATCH($A30, 'ADR Tracking'!$A:$A, 0), ), COLUMN()-4 ), INDEX('ADR Tracking'!$G:$ZX, MATCH($A30, 'ADR Tracking'!$A:$A, 0), ), 0 ) ), "" )
A31: SRP8-039 | B31: Powertrain Electronics | C31: Powertrain | D31: Energy Systems | E31: =IFERROR( INDEX('Project Assignment Check'!$G$1:$ZX$1, MATCH( LARGE( INDEX('ADR Tracking'!$G:$ZX, MATCH($A31, 'ADR Tracking'!$A:$A, 0), ), COLUMN()-4 ), INDEX('ADR Tracking'!$G:$ZX, MATCH($A31, 'ADR Tracking'!$A:$A, 0), ), 0 ) ), "" ) -> ADR-113 | F31: =IFERROR( INDEX('Project Assignment Check'!$G$1:$ZX$1, MATCH( LARGE( INDEX('ADR Tracking'!$G:$ZX, MATCH($A31, 'ADR Tracking'!$A:$A, 0), ), COLUMN()-4 ), INDEX('ADR Tracking'!$G:$ZX, MATCH($A31, 'ADR Tracking'!$A:$A, 0), ), 0 ) ), "" ) -> ADR-109 | G31: =IFERROR( INDEX('Project Assignment Check'!$G$1:$ZX$1, MATCH( LARGE( INDEX('ADR Tracking'!$G:$ZX, MATCH($A31, 'ADR Tracking'!$A:$A, 0), ), COLUMN()-4 ), INDEX('ADR Tracking'!$G:$ZX, MATCH($A31, 'ADR Tracking'!$A:$A, 0), ), 0 ) ), "" ) | H31: =IFERROR( INDEX('Project Assignment Check'!$G$1:$ZX$1, MATCH( LARGE( INDEX('ADR Tracking'!$G:$ZX, MATCH($A31, 'ADR Tracking'!$A:$A, 0), ), COLUMN()-4 ), INDEX('ADR Tracking'!$G:$ZX, MATCH($A31, 'ADR Tracking'!$A:$A, 0), ), 0 ) ), "" ) | I31: =IFERROR( INDEX('Project Assignment Check'!$G$1:$ZX$1, MATCH( LARGE( INDEX('ADR Tracking'!$G:$ZX, MATCH($A31, 'ADR Tracking'!$A:$A, 0), ), COLUMN()-4 ), INDEX('ADR Tracking'!$G:$ZX, MATCH($A31, 'ADR Tracking'!$A:$A, 0), ), 0 ) ), "" ) | J31: =IFERROR( INDEX('Project Assignment Check'!$G$1:$ZX$1, MATCH( LARGE( INDEX('ADR Tracking'!$G:$ZX, MATCH($A31, 'ADR Tracking'!$A:$A, 0), ), COLUMN()-4 ), INDEX('ADR Tracking'!$G:$ZX, MATCH($A31, 'ADR Tracking'!$A:$A, 0), ), 0 ) ), "" )
A32: SRP8-043 | B32: Front Suspension | C32: Vehicle Dynamics | D32: Chassis & Bodywork | E32: =IFERROR( INDEX('Project Assignment Check'!$G$1:$ZX$1, MATCH( LARGE( INDEX('ADR Tracking'!$G:$ZX, MATCH($A32, 'ADR Tracking'!$A:$A, 0), ), COLUMN()-4 ), INDEX('ADR Tracking'!$G:$ZX, MATCH($A32, 'ADR Tracking'!$A:$A, 0), ), 0 ) ), "" ) -> ADR-90 | F32: =IFERROR( INDEX('Project Assignment Check'!$G$1:$ZX$1, MATCH( LARGE( INDEX('ADR Tracking'!$G:$ZX, MATCH($A32, 'ADR Tracking'!$A:$A, 0), ), COLUMN()-4 ), INDEX('ADR Tracking'!$G:$ZX, MATCH($A32, 'ADR Tracking'!$A:$A, 0), ), 0 ) ), "" ) | G32: =IFERROR( INDEX('Project Assignment Check'!$G$1:$ZX$1, MATCH( LARGE( INDEX('ADR Tracking'!$G:$ZX, MATCH($A32, 'ADR Tracking'!$A:$A, 0), ), COLUMN()-4 ), INDEX('ADR Tracking'!$G:$ZX, MATCH($A32, 'ADR Tracking'!$A:$A, 0), ), 0 ) ), "" ) | H32: =IFERROR( INDEX('Project Assignment Check'!$G$1:$ZX$1, MATCH( LARGE( INDEX('ADR Tracking'!$G:$ZX, MATCH($A32, 'ADR Tracking'!$A:$A, 0), ), COLUMN()-4 ), INDEX('ADR Tracking'!$G:$ZX, MATCH($A32, 'ADR Tracking'!$A:$A, 0), ), 0 ) ), "" ) | I32: =IFERROR( INDEX('Project Assignment Check'!$G$1:$ZX$1, MATCH( LARGE( INDEX('ADR Tracking'!$G:$ZX, MATCH($A32, 'ADR Tracking'!$A:$A, 0), ), COLUMN()-4 ), INDEX('ADR Tracking'!$G:$ZX, MATCH($A32, 'ADR Tracking'!$A:$A, 0), ), 0 ) ), "" ) | J32: =IFERROR( INDEX('Project Assignment Check'!$G$1:$ZX$1, MATCH( LARGE( INDEX('ADR Tracking'!$G:$ZX, MATCH($A32, 'ADR Tracking'!$A:$A, 0), ), COLUMN()-4 ), INDEX('ADR Tracking'!$G:$ZX, MATCH($A32, 'ADR Tracking'!$A:$A, 0), ), 0 ) ), "" )
A33: SRP8-044 | B33: Rear Suspension | C33: Vehicle Dynamics | D33: Chassis & Bodywork | E33: =IFERROR( INDEX('Project Assignment Check'!$G$1:$ZX$1, MATCH( LARGE( INDEX('ADR Tracking'!$G:$ZX, MATCH($A33, 'ADR Tracking'!$A:$A, 0), ), COLUMN()-4 ), INDEX('ADR Tracking'!$G:$ZX, MATCH($A33, 'ADR Tracking'!$A:$A, 0), ), 0 ) ), "" ) | F33: =IFERROR( INDEX('Project Assignment Check'!$G$1:$ZX$1, MATCH( LARGE( INDEX('ADR Tracking'!$G:$ZX, MATCH($A33, 'ADR Tracking'!$A:$A, 0), ), COLUMN()-4 ), INDEX('ADR Tracking'!$G:$ZX, MATCH($A33, 'ADR Tracking'!$A:$A, 0), ), 0 ) ), "" ) | G33: =IFERROR( INDEX('Project Assignment Check'!$G$1:$ZX$1, MATCH( LARGE( INDEX('ADR Tracking'!$G:$ZX, MATCH($A33, 'ADR Tracking'!$A:$A, 0), ), COLUMN()-4 ), INDEX('ADR Tracking'!$G:$ZX, MATCH($A33, 'ADR Tracking'!$A:$A, 0), ), 0 ) ), "" ) | H33: =IFERROR( INDEX('Project Assignment Check'!$G$1:$ZX$1, MATCH( LARGE( INDEX('ADR Tracking'!$G:$ZX, MATCH($A33, 'ADR Tracking'!$A:$A, 0), ), COLUMN()-4 ), INDEX('ADR Tracking'!$G:$ZX, MATCH($A33, 'ADR Tracking'!$A:$A, 0), ), 0 ) ), "" ) | I33: =IFERROR( INDEX('Project Assignment Check'!$G$1:$ZX$1, MATCH( LARGE( INDEX('ADR Tracking'!$G:$ZX, MATCH($A33, 'ADR Tracking'!$A:$A, 0), ), COLUMN()-4 ), INDEX('ADR Tracking'!$G:$ZX, MATCH($A33, 'ADR Tracking'!$A:$A, 0), ), 0 ) ), "" ) | J33: =IFERROR( INDEX('Project Assignment Check'!$G$1:$ZX$1, MATCH( LARGE( INDEX('ADR Tracking'!$G:$ZX, MATCH($A33, 'ADR Tracking'!$A:$A, 0), ), COLUMN()-4 ), INDEX('ADR Tracking'!$G:$ZX, MATCH($A33, 'ADR Tracking'!$A:$A, 0), ), 0 ) ), "" )
A34: SRP8-045 | B34: Front Brakes | C34: Vehicle Dynamics | E34: =IFERROR( INDEX('Project Assignment Check'!$G$1:$ZX$1, MATCH( LARGE( INDEX('ADR Tracking'!$G:$ZX, MATCH($A34, 'ADR Tracking'!$A:$A, 0), ), COLUMN()-4 ), INDEX('ADR Tracking'!$G:$ZX, MATCH($A34, 'ADR Tracking'!$A:$A, 0), ), 0 ) ), "" ) -> ADR-31 | F34: =IFERROR( INDEX('Project Assignment Check'!$G$1:$ZX$1, MATCH( LARGE( INDEX('ADR Tracking'!$G:$ZX, MATCH($A34, 'ADR Tracking'!$A:$A, 0), ), COLUMN()-4 ), INDEX('ADR Tracking'!$G:$ZX, MATCH($A34, 'ADR Tracking'!$A:$A, 0), ), 0 ) ), "" ) -> ADR-42 | G34: =IFERROR( INDEX('Project Assignment Check'!$G$1:$ZX$1, MATCH( LARGE( INDEX('ADR Tracking'!$G:$ZX, MATCH($A34, 'ADR Tracking'!$A:$A, 0), ), COLUMN()-4 ), INDEX('ADR Tracking'!$G:$ZX, MATCH($A34, 'ADR Tracking'!$A:$A, 0), ), 0 ) ), "" ) -> ADR-90 | H34: =IFERROR( INDEX('Project Assignment Check'!$G$1:$ZX$1, MATCH( LARGE( INDEX('ADR Tracking'!$G:$ZX, MATCH($A34, 'ADR Tracking'!$A:$A, 0), ), COLUMN()-4 ), INDEX('ADR Tracking'!$G:$ZX, MATCH($A34, 'ADR Tracking'!$A:$A, 0), ), 0 ) ), "" ) | I34: =IFERROR( INDEX('Project Assignment Check'!$G$1:$ZX$1, MATCH( LARGE( INDEX('ADR Tracking'!$G:$ZX, MATCH($A34, 'ADR Tracking'!$A:$A, 0), ), COLUMN()-4 ), INDEX('ADR Tracking'!$G:$ZX, MATCH($A34, 'ADR Tracking'!$A:$A, 0), ), 0 ) ), "" ) | J34: =IFERROR( INDEX('Project Assignment Check'!$G$1:$ZX$1, MATCH( LARGE( INDEX('ADR Tracking'!$G:$ZX, MATCH($A34, 'ADR Tracking'!$A:$A, 0), ), COLUMN()-4 ), INDEX('ADR Tracking'!$G:$ZX, MATCH($A34, 'ADR Tracking'!$A:$A, 0), ), 0 ) ), "" )
A35: SRP8-046 | B35: Rear Brakes | C35: Vehicle Dynamics | E35: =IFERROR( INDEX('Project Assignment Check'!$G$1:$ZX$1, MATCH( LARGE( INDEX('ADR Tracking'!$G:$ZX, MATCH($A35, 'ADR Tracking'!$A:$A, 0), ), COLUMN()-4 ), INDEX('ADR Tracking'!$G:$ZX, MATCH($A35, 'ADR Tracking'!$A:$A, 0), ), 0 ) ), "" ) -> ADR-31 | F35: =IFERROR( INDEX('Project Assignment Check'!$G$1:$ZX$1, MATCH( LARGE( INDEX('ADR Tracking'!$G:$ZX, MATCH($A35, 'ADR Tracking'!$A:$A, 0), ), COLUMN()-4 ), INDEX('ADR Tracking'!$G:$ZX, MATCH($A35, 'ADR Tracking'!$A:$A, 0), ), 0 ) ), "" ) -> ADR-42 | G35: =IFERROR( INDEX('Project Assignment Check'!$G$1:$ZX$1, MATCH( LARGE( INDEX('ADR Tracking'!$G:$ZX, MATCH($A35, 'ADR Tracking'!$A:$A, 0), ), COLUMN()-4 ), INDEX('ADR Tracking'!$G:$ZX, MATCH($A35, 'ADR Tracking'!$A:$A, 0), ), 0 ) ), "" ) | H35: =IFERROR( INDEX('Project Assignment Check'!$G$1:$ZX$1, MATCH( LARGE( INDEX('ADR Tracking'!$G:$ZX, MATCH($A35, 'ADR Tracking'!$A:$A, 0), ), COLUMN()-4 ), INDEX('ADR Tracking'!$G:$ZX, MATCH($A35, 'ADR Tracking'!$A:$A, 0), ), 0 ) ), "" ) | I35: =IFERROR( INDEX('Project Assignment Check'!$G$1:$ZX$1, MATCH( LARGE( INDEX('ADR Tracking'!$G:$ZX, MATCH($A35, 'ADR Tracking'!$A:$A, 0), ), COLUMN()-4 ), INDEX('ADR Tracking'!$G:$ZX, MATCH($A35, 'ADR Tracking'!$A:$A, 0), ), 0 ) ), "" ) | J35: =IFERROR( INDEX('Project Assignment Check'!$G$1:$ZX$1, MATCH( LARGE( INDEX('ADR Tracking'!$G:$ZX, MATCH($A35, 'ADR Tracking'!$A:$A, 0), ), COLUMN()-4 ), INDEX('ADR Tracking'!$G:$ZX, MATCH($A35, 'ADR Tracking'!$A:$A, 0), ), 0 ) ), "" )
A36: SRP8-047 | B36: Handbrake | C36: Vehicle Dynamics | D36: Interior | E36: =IFERROR( INDEX('Project Assignment Check'!$G$1:$ZX$1, MATCH( LARGE( INDEX('ADR Tracking'!$G:$ZX, MATCH($A36, 'ADR Tracking'!$A:$A, 0), ), COLUMN()-4 ), INDEX('ADR Tracking'!$G:$ZX, MATCH($A36, 'ADR Tracking'!$A:$A, 0), ), 0 ) ), "" ) -> ADR-31 | F36: =IFERROR( INDEX('Project Assignment Check'!$G$1:$ZX$1, MATCH( LARGE( INDEX('ADR Tracking'!$G:$ZX, MATCH($A36, 'ADR Tracking'!$A:$A, 0), ), COLUMN()-4 ), INDEX('ADR Tracking'!$G:$ZX, MATCH($A36, 'ADR Tracking'!$A:$A, 0), ), 0 ) ), "" ) | G36: =IFERROR( INDEX('Project Assignment Check'!$G$1:$ZX$1, MATCH( LARGE( INDEX('ADR Tracking'!$G:$ZX, MATCH($A36, 'ADR Tracking'!$A:$A, 0), ), COLUMN()-4 ), INDEX('ADR Tracking'!$G:$ZX, MATCH($A36, 'ADR Tracking'!$A:$A, 0), ), 0 ) ), "" ) | H36: =IFERROR( INDEX('Project Assignment Check'!$G$1:$ZX$1, MATCH( LARGE( INDEX('ADR Tracking'!$G:$ZX, MATCH($A36, 'ADR Tracking'!$A:$A, 0), ), COLUMN()-4 ), INDEX('ADR Tracking'!$G:$ZX, MATCH($A36, 'ADR Tracking'!$A:$A, 0), ), 0 ) ), "" ) | I36: =IFERROR( INDEX('Project Assignment Check'!$G$1:$ZX$1, MATCH( LARGE( INDEX('ADR Tracking'!$G:$ZX, MATCH($A36, 'ADR Tracking'!$A:$A, 0), ), COLUMN()-4 ), INDEX('ADR Tracking'!$G:$ZX, MATCH($A36, 'ADR Tracking'!$A:$A, 0), ), 0 ) ), "" ) | J36: =IFERROR( INDEX('Project Assignment Check'!$G$1:$ZX$1, MATCH( LARGE( INDEX('ADR Tracking'!$G:$ZX, MATCH($A36, 'ADR Tracking'!$A:$A, 0), ), COLUMN()-4 ), INDEX('ADR Tracking'!$G:$ZX, MATCH($A36, 'ADR Tracking'!$A:$A, 0), ), 0 ) ), "" )
A37: SRP8-048 | B37: Steering Column | C37: Vehicle Dynamics | D37: Chassis & Bodywork | E37: =IFERROR( INDEX('Project Assignment Check'!$G$1:$ZX$1, MATCH( LARGE( INDEX('ADR Tracking'!$G:$ZX, MATCH($A37, 'ADR Tracking'!$A:$A, 0), ), COLUMN()-4 ), INDEX('ADR Tracking'!$G:$ZX, MATCH($A37, 'ADR Tracking'!$A:$A, 0), ), 0 ) ), "" ) -> ADR-10 | F37: =IFERROR( INDEX('Project Assignment Check'!$G$1:$ZX$1, MATCH( LARGE( INDEX('ADR Tracking'!$G:$ZX, MATCH($A37, 'ADR Tracking'!$A:$A, 0), ), COLUMN()-4 ), INDEX('ADR Tracking'!$G:$ZX, MATCH($A37, 'ADR Tracking'!$A:$A, 0), ), 0 ) ), "" ) -> ADR-90 | G37: =IFERROR( INDEX('Project Assignment Check'!$G$1:$ZX$1, MATCH( LARGE( INDEX('ADR Tracking'!$G:$ZX, MATCH($A37, 'ADR Tracking'!$A:$A, 0), ), COLUMN()-4 ), INDEX('ADR Tracking'!$G:$ZX, MATCH($A37, 'ADR Tracking'!$A:$A, 0), ), 0 ) ), "" ) | H37: =IFERROR( INDEX('Project Assignment Check'!$G$1:$ZX$1, MATCH( LARGE( INDEX('ADR Tracking'!$G:$ZX, MATCH($A37, 'ADR Tracking'!$A:$A, 0), ), COLUMN()-4 ), INDEX('ADR Tracking'!$G:$ZX, MATCH($A37, 'ADR Tracking'!$A:$A, 0), ), 0 ) ), "" ) | I37: =IFERROR( INDEX('Project Assignment Check'!$G$1:$ZX$1, MATCH( LARGE( INDEX('ADR Tracking'!$G:$ZX, MATCH($A37, 'ADR Tracking'!$A:$A, 0), ), COLUMN()-4 ), INDEX('ADR Tracking'!$G:$ZX, MATCH($A37, 'ADR Tracking'!$A:$A, 0), ), 0 ) ), "" ) | J37: =IFERROR( INDEX('Project Assignment Check'!$G$1:$ZX$1, MATCH( LARGE( INDEX('ADR Tracking'!$G:$ZX, MATCH($A37, 'ADR Tracking'!$A:$A, 0), ), COLUMN()-4 ), INDEX('ADR Tracking'!$G:$ZX, MATCH($A37, 'ADR Tracking'!$A:$A, 0), ), 0 ) ), "" )
A38: SRP8-049 | B38: Steering Rack | C38: Vehicle Dynamics | D38: Chassis & Bodywork | E38: =IFERROR( INDEX('Project Assignment Check'!$G$1:$ZX$1, MATCH( LARGE( INDEX('ADR Tracking'!$G:$ZX, MATCH($A38, 'ADR Tracking'!$A:$A, 0), ), COLUMN()-4 ), INDEX('ADR Tracking'!$G:$ZX, MATCH($A38, 'ADR Tracking'!$A:$A, 0), ), 0 ) ), "" ) -> ADR-90 | F38: =IFERROR( INDEX('Project Assignment Check'!$G$1:$ZX$1, MATCH( LARGE( INDEX('ADR Tracking'!$G:$ZX, MATCH($A38, 'ADR Tracking'!$A:$A, 0), ), COLUMN()-4 ), INDEX('ADR Tracking'!$G:$ZX, MATCH($A38, 'ADR Tracking'!$A:$A, 0), ), 0 ) ), "" ) -> ADR-43 | G38: =IFERROR( INDEX('Project Assignment Check'!$G$1:$ZX$1, MATCH( LARGE( INDEX('ADR Tracking'!$G:$ZX, MATCH($A38, 'ADR Tracking'!$A:$A, 0), ), COLUMN()-4 ), INDEX('ADR Tracking'!$G:$ZX, MATCH($A38, 'ADR Tracking'!$A:$A, 0), ), 0 ) ), "" ) | H38: =IFERROR( INDEX('Project Assignment Check'!$G$1:$ZX$1, MATCH( LARGE( INDEX('ADR Tracking'!$G:$ZX, MATCH($A38, 'ADR Tracking'!$A:$A, 0), ), COLUMN()-4 ), INDEX('ADR Tracking'!$G:$ZX, MATCH($A38, 'ADR Tracking'!$A:$A, 0), ), 0 ) ), "" ) | I38: =IFERROR( INDEX('Project Assignment Check'!$G$1:$ZX$1, MATCH( LARGE( INDEX('ADR Tracking'!$G:$ZX, MATCH($A38, 'ADR Tracking'!$A:$A, 0), ), COLUMN()-4 ), INDEX('ADR Tracking'!$G:$ZX, MATCH($A38, 'ADR Tracking'!$A:$A, 0), ), 0 ) ), "" ) | J38: =IFERROR( INDEX('Project Assignment Check'!$G$1:$ZX$1, MATCH( LARGE( INDEX('ADR Tracking'!$G:$ZX, MATCH($A38, 'ADR Tracking'!$A:$A, 0), ), COLUMN()-4 ), INDEX('ADR Tracking'!$G:$ZX, MATCH($A38, 'ADR Tracking'!$A:$A, 0), ), 0 ) ), "" )
